<?xml version="1.0" encoding="utf-8"?>
<!-- =================================================================================== -->
<!-- |    This document was autogenerated by xacro from rocr_integration.urdf.xacro    | -->
<!-- |    EDITING THIS FILE BY HAND IS NOT RECOMMENDED                                 | -->
<!-- =================================================================================== -->
<!-- Name your robot here -->
<robot name="rocr">
  <link name="dummy_link"/>
  <joint name="dummy_joint" type="fixed">
    <parent link="dummy_link"/>
    <child link="base_link"/>
  </joint>
  <link name="base_link">
    <inertial>
      <origin rpy="0 0 0" xyz="-0.107763369330454 -0.0445 -0.020198432861837"/>
      <mass value="10.6823173170711"/>
      <inertia ixx="0.0124898425373309" ixy="2.21422874211196E-18" ixz="0.00348506285187222" iyy="0.0524375502212246" iyz="-4.51307480905537E-19" izz="0.0537557242577893"/>
    </inertial>
    <visual>
      <origin rpy="0 0 0" xyz="0 0 0"/>
      <geometry>
        <mesh filename="package://rocr/meshes/base_link.STL"/>
      </geometry>
      <material name="">
        <color rgba="0.650980392156863 0.619607843137255 0.588235294117647 1"/>
      </material>
    </visual>
    <collision>
      <origin rpy="0 0 0" xyz="0 0 0"/>
      <geometry>
        <mesh filename="package://rocr/meshes/base_link.STL"/>
      </geometry>
    </collision>
  </link>
  <link name="link_right_arm">
    <inertial>
      <origin rpy="0 0 0" xyz="0.105749170017255 0.041732238071937 0.0282872144318269"/>
      <mass value="0.165316765586137"/>
      <inertia ixx="0.000610620746206452" ixy="-0.000197454180877903" ixz="-0.000122729645879153" iyy="0.000702185352603574" iyz="-0.000186690232637552" izz="0.000631933215587882"/>
    </inertial>
    <visual>
      <origin rpy="0 0 0" xyz="0 0 0"/>
      <geometry>
        <mesh filename="package://rocr/meshes/link_right_arm.STL"/>
      </geometry>
      <material name="">
        <color rgba="0.792156862745098 0.819607843137255 0.933333333333333 1"/>
      </material>
    </visual>
    <collision>
      <origin rpy="0 0 0" xyz="0 0 0"/>
      <geometry>
        <mesh filename="package://rocr/meshes/link_right_arm.STL"/>
      </geometry>
    </collision>
  </link>
  <joint name="joint_right_arm" type="prismatic">
    <origin rpy="1.5708 0 0" xyz="-0.36753 0 -0.072"/>
    <parent link="base_link"/>
    <child link="link_right_arm"/>
    <axis xyz="0 0 1"/>
    <limit effort="1" lower="-1.5" upper="3.5" velocity="0.2"/>
  </joint>
  <link name="link_left_arm">
    <inertial>
      <origin rpy="0 0 0" xyz="-0.0655989557893637 0.0418008535608141 0.127140611347727"/>
      <mass value="0.160992890586137"/>
      <inertia ixx="0.000595308316329433" ixy="-8.90928279875958E-05" ixz="5.62513948424324E-05" iyy="0.000548684708610842" iyz="0.000182030001506834" izz="0.000479899493032254"/>
    </inertial>
    <visual>
      <origin rpy="0 0 0" xyz="0 0 0"/>
      <geometry>
        <mesh filename="package://rocr/meshes/link_left_arm.STL"/>
      </geometry>
      <material name="">
        <color rgba="0.792156862745098 0.819607843137255 0.933333333333333 1"/>
      </material>
    </visual>
    <collision>
      <origin rpy="0 0 0" xyz="0 0 0"/>
      <geometry>
        <mesh filename="package://rocr/meshes/link_left_arm.STL"/>
      </geometry>
    </collision>
  </link>
  <joint name="joint_left_arm" type="prismatic">
    <origin rpy="1.5708 0 0" xyz="-0.214 0.066422 -0.072"/>
    <parent link="base_link"/>
    <child link="link_left_arm"/>
    <axis xyz="0 0 1"/>
    <limit effort="1" lower="-1.5" upper="3.5" velocity="0.2"/>
  </joint>
  <link name="link_rear_axle">
    <inertial>
      <origin rpy="0 0 0" xyz="0 0 0.0445"/>
      <mass value="0.0152217234982576"/>
      <inertia ixx="1.19398821903406E-05" ixy="-1.91230860492601E-39" ixz="1.88140042004344E-23" iyy="1.19398821903406E-05" iyz="-2.0993020771577E-37" izz="5.46798234902396E-08"/>
    </inertial>
    <visual>
      <origin rpy="0 0 0" xyz="0 0 0"/>
      <geometry>
        <mesh filename="package://rocr/meshes/link_rear_axle.STL"/>
      </geometry>
      <material name="">
        <color rgba="0.650980392156863 0.619607843137255 0.588235294117647 1"/>
      </material>
    </visual>
    <collision>
      <origin rpy="0 0 0" xyz="0 0 0"/>
      <geometry>
        <mesh filename="package://rocr/meshes/link_rear_axle.STL"/>
      </geometry>
    </collision>
  </link>
  <joint name="joint_rear_axle" type="continuous">
    <origin rpy="1.5708 0 0" xyz="-0.04 0 -0.0616"/>
    <parent link="base_link"/>
    <child link="link_rear_axle"/>
    <axis xyz="0 0 1"/>
  </joint>
  <link name="link_rear_right_rim">
    <inertial>
      <origin rpy="0 0 0" xyz="0 -6.93889390390723E-18 0.00655335417593042"/>
      <mass value="0.0269891429421557"/>
      <inertia ixx="1.06871584170568E-06" ixy="-4.82050818462486E-23" ixz="-5.58242963112347E-23" iyy="1.06871584170568E-06" iyz="-7.78986618612618E-23" izz="1.59499688104541E-06"/>
    </inertial>
    <visual>
      <origin rpy="0 0 0" xyz="0 0 0"/>
      <geometry>
        <mesh filename="package://rocr/meshes/link_rear_right_rim.STL"/>
      </geometry>
      <material name="">
        <color rgba="0.650980392156863 0.619607843137255 0.588235294117647 1"/>
      </material>
    </visual>
    <collision>
      <origin rpy="0 0 0" xyz="0 0 0"/>
      <geometry>
        <mesh filename="package://rocr/meshes/link_rear_right_rim.STL"/>
      </geometry>
    </collision>
  </link>
  <joint name="joint_rear_right_rim" type="fixed">
    <origin rpy="0 0 0" xyz="0 0 0"/>
    <parent link="link_rear_axle"/>
    <child link="link_rear_right_rim"/>
    <axis xyz="0 0 0"/>
  </joint>
  <link name="link_rear_right_tyre">
    <inertial>
      <origin rpy="0 0 0" xyz="6.93889390390723E-18 0 0.00599999999999999"/>
      <mass value="0.00176187281891002"/>
      <inertia ixx="1.38738251479273E-07" ixy="-2.76591370085178E-39" ixz="3.18518483981357E-38" iyy="1.38738251479273E-07" iyz="-9.19988344967612E-40" izz="2.34006429114269E-07"/>
    </inertial>
    <visual>
      <origin rpy="0 0 0" xyz="0 0 0"/>
      <geometry>
        <mesh filename="package://rocr/meshes/link_rear_right_tyre.STL"/>
      </geometry>
      <material name="">
        <color rgba="0.298039215686275 0.298039215686275 0.298039215686275 1"/>
      </material>
    </visual>
    <collision>
      <origin rpy="0 0 0" xyz="0 0 0"/>
      <geometry>
        <mesh filename="package://rocr/meshes/link_rear_right_tyre.STL"/>
      </geometry>
    </collision>
  </link>
  <joint name="joint_rear_right_tyre" type="fixed">
    <origin rpy="0 0 0" xyz="0 0 0"/>
    <parent link="link_rear_right_rim"/>
    <child link="link_rear_right_tyre"/>
    <axis xyz="0 0 0"/>
  </joint>
  <link name="link_rear_left_rim">
    <inertial>
      <origin rpy="0 0 0" xyz="0 -6.93889390390723E-18 0.00655335417593042"/>
      <mass value="0.0269891429421556"/>
      <inertia ixx="1.06871584170568E-06" ixy="1.05879118406788E-22" ixz="-8.69058866923709E-23" iyy="1.06871584170568E-06" iyz="4.5606138607735E-23" izz="1.59499688104541E-06"/>
    </inertial>
    <visual>
      <origin rpy="0 0 0" xyz="0 0 0"/>
      <geometry>
        <mesh filename="package://rocr/meshes/link_rear_left_rim.STL"/>
      </geometry>
      <material name="">
        <color rgba="0.650980392156863 0.619607843137255 0.588235294117647 1"/>
      </material>
    </visual>
    <collision>
      <origin rpy="0 0 0" xyz="0 0 0"/>
      <geometry>
        <mesh filename="package://rocr/meshes/link_rear_left_rim.STL"/>
      </geometry>
    </collision>
  </link>
  <joint name="joint_rear_left_rim" type="fixed">
    <origin rpy="3.1416 0 -2.7485" xyz="0 0 0.089"/>
    <parent link="link_rear_axle"/>
    <child link="link_rear_left_rim"/>
    <axis xyz="0 0 0"/>
  </joint>
  <link name="link_rear_left_tyre">
    <inertial>
      <origin rpy="0 0 0" xyz="0 0 0.00599999999999998"/>
      <mass value="0.00176187281891002"/>
      <inertia ixx="1.38738251479272E-07" ixy="-2.76591370085178E-39" ixz="-5.29395592033935E-24" iyy="1.38738251479272E-07" iyz="-9.19988344967613E-40" izz="2.34006429114269E-07"/>
    </inertial>
    <visual>
      <origin rpy="0 0 0" xyz="0 0 0"/>
      <geometry>
        <mesh filename="package://rocr/meshes/link_rear_left_tyre.STL"/>
      </geometry>
      <material name="">
        <color rgba="0.298039215686275 0.298039215686275 0.298039215686275 1"/>
      </material>
    </visual>
    <collision>
      <origin rpy="0 0 0" xyz="0 0 0"/>
      <geometry>
        <mesh filename="package://rocr/meshes/link_rear_left_tyre.STL"/>
      </geometry>
    </collision>
  </link>
  <joint name="joint_rear_left_tyre" type="fixed">
    <origin rpy="3.14159265358979 0 -2.74849784316327" xyz="0 0 0.012"/>
    <parent link="link_rear_left_rim"/>
    <child link="link_rear_left_tyre"/>
    <axis xyz="0 0 0"/>
  </joint>
  <link name="link_front_left_axle">
    <inertial>
      <origin rpy="0 0 0" xyz="0.00270152340084262 -0.0147521862352328 -3.59055389309582E-08"/>
      <mass value="0.00980151610171137"/>
      <inertia ixx="1.13698362232884E-06" ixy="3.24392869633284E-07" ixz="-1.79913538752389E-12" iyy="3.12651828844893E-07" iyz="-1.18488336245529E-12" izz="1.38231713607358E-06"/>
    </inertial>
    <visual>
      <origin rpy="0 0 0" xyz="0 0 0"/>
      <geometry>
        <mesh filename="package://rocr/meshes/link_front_left_axle.STL"/>
      </geometry>
      <material name="">
        <color rgba="0.650980392156863 0.619607843137255 0.588235294117647 1"/>
      </material>
    </visual>
    <collision>
      <origin rpy="0 0 0" xyz="0 0 0"/>
      <geometry>
        <mesh filename="package://rocr/meshes/link_front_left_axle.STL"/>
      </geometry>
    </collision>
  </link>
  <joint name="joint_front_left_axle" type="continuous">
    <origin rpy="1.5708 0 -1.6484" xyz="-0.16 -0.074 -0.0346"/>
    <parent link="base_link"/>
    <child link="link_front_left_axle"/>
    <axis xyz="0 1 0"/>
    <limit effort="1" lower="0" upper="0.0" velocity="0"/>
  </joint>
  <link name="link_front_left_rim">
    <inertial>
      <origin rpy="0 0 0" xyz="2.77555756156289E-17 2.60208521396521E-17 -0.00537451041392963"/>
      <mass value="0.0269891429421557"/>
      <inertia ixx="1.06871584170568E-06" ixy="2.1237862227299E-22" ixz="-3.04402465419514E-22" iyy="1.06871584170568E-06" iyz="4.96308367531817E-23" izz="1.59499688104541E-06"/>
    </inertial>
    <visual>
      <origin rpy="0 0 0" xyz="0 0 0"/>
      <geometry>
        <mesh filename="package://rocr/meshes/link_front_left_rim.STL"/>
      </geometry>
      <material name="">
        <color rgba="0.650980392156863 0.619607843137255 0.588235294117647 1"/>
      </material>
    </visual>
    <collision>
      <origin rpy="0 0 0" xyz="0 0 0"/>
      <geometry>
        <mesh filename="package://rocr/meshes/link_front_left_rim.STL"/>
      </geometry>
    </collision>
  </link>
  <joint name="joint_front_left_rim" type="continuous">
    <origin rpy="-1.5708 1.1039 1.5708" xyz="0.0030721 -0.027 0"/>
    <parent link="link_front_left_axle"/>
    <child link="link_front_left_rim"/>
    <axis xyz="0 0 1"/>
  </joint>
  <link name="link_front_left_tyre">
    <inertial>
      <origin rpy="0 0 0" xyz="1.38777878078145E-17 -8.32667268468867E-17 0.00592786458986008"/>
      <mass value="0.00176187281891002"/>
      <inertia ixx="1.38738251479274E-07" ixy="3.23117426778526E-24" ixz="-4.19794160870662E-23" iyy="1.38738251479274E-07" iyz="7.44462551297725E-24" izz="2.34006429114269E-07"/>
    </inertial>
    <visual>
      <origin rpy="0 0 0" xyz="0 0 0"/>
      <geometry>
        <mesh filename="package://rocr/meshes/link_front_left_tyre.STL"/>
      </geometry>
      <material name="">
        <color rgba="0.298039215686275 0.298039215686275 0.298039215686275 1"/>
      </material>
    </visual>
    <collision>
      <origin rpy="0 0 0" xyz="0 0 0"/>
      <geometry>
        <mesh filename="package://rocr/meshes/link_front_left_tyre.STL"/>
      </geometry>
    </collision>
  </link>
  <joint name="joint_front_left_tyre" type="fixed">
    <origin rpy="3.1416 0 -0.81007" xyz="0 0 0"/>
    <parent link="link_front_left_rim"/>
    <child link="link_front_left_tyre"/>
    <axis xyz="0 0 0"/>
  </joint>
  <link name="link_front_right_axle">
    <inertial>
      <origin rpy="0 0 0" xyz="0.00270152786594034 -0.0147521828374566 -6.07548128472857E-09"/>
      <mass value="0.00980150843161576"/>
      <inertia ixx="1.13698316819975E-06" ixy="3.2439295105602E-07" ixz="-7.75777245952202E-13" iyy="3.12651719169867E-07" iyz="-4.26144996246123E-13" izz="1.38231670444798E-06"/>
    </inertial>
    <visual>
      <origin rpy="0 0 0" xyz="0 0 0"/>
      <geometry>
        <mesh filename="package://rocr/meshes/link_front_right_axle.STL"/>
      </geometry>
      <material name="">
        <color rgba="0.650980392156863 0.619607843137255 0.588235294117647 1"/>
      </material>
    </visual>
    <collision>
      <origin rpy="0 0 0" xyz="0 0 0"/>
      <geometry>
        <mesh filename="package://rocr/meshes/link_front_right_axle.STL"/>
      </geometry>
    </collision>
  </link>
  <joint name="joint_front_right_axle" type="continuous">
    <origin rpy="1.5708 0 1.5708" xyz="-0.16 -0.015 -0.0346"/>
    <parent link="base_link"/>
    <child link="link_front_right_axle"/>
    <axis xyz="0 1 0"/>
    <limit effort="1" lower="0" upper="0" velocity="0"/>
  </joint>
  <link name="link_front_right_rim">
    <inertial>
      <origin rpy="0 0 0" xyz="2.77555756156289E-17 2.77555756156289E-17 -0.00544664582406959"/>
      <mass value="0.0269891429421557"/>
      <inertia ixx="1.06871584170567E-06" ixy="5.29395592033938E-23" ixz="1.73164791753298E-22" iyy="1.06871584170567E-06" iyz="7.51528398613046E-23" izz="1.59499688104541E-06"/>
    </inertial>
    <visual>
      <origin rpy="0 0 0" xyz="0 0 0"/>
      <geometry>
        <mesh filename="package://rocr/meshes/link_front_right_rim.STL"/>
      </geometry>
      <material name="">
        <color rgba="0.650980392156863 0.619607843137255 0.588235294117647 1"/>
      </material>
    </visual>
    <collision>
      <origin rpy="0 0 0" xyz="0 0 0"/>
      <geometry>
        <mesh filename="package://rocr/meshes/link_front_right_rim.STL"/>
      </geometry>
    </collision>
  </link>
  <joint name="joint_front_right_rim" type="continuous">
    <origin rpy="1.5708 -0.93241 -1.5708" xyz="0.003 -0.027 0"/>
    <parent link="link_front_right_axle"/>
    <child link="link_front_right_rim"/>
    <axis xyz="0 0 1"/>
  </joint>
  <link name="link_front_right_tyre">
    <inertial>
      <origin rpy="0 0 0" xyz="0 0 0.00599999999999997"/>
      <mass value="0.00176187281891002"/>
      <inertia ixx="1.38738251479273E-07" ixy="-2.76591370085178E-39" ixz="3.18518483981357E-38" iyy="1.38738251479273E-07" iyz="-9.19988344967612E-40" izz="2.34006429114269E-07"/>
    </inertial>
    <visual>
      <origin rpy="0 0 0" xyz="0 0 0"/>
      <geometry>
        <mesh filename="package://rocr/meshes/link_front_right_tyre.STL"/>
      </geometry>
      <material name="">
        <color rgba="0.298039215686275 0.298039215686275 0.298039215686275 1"/>
      </material>
    </visual>
    <collision>
      <origin rpy="0 0 0" xyz="0 0 0"/>
      <geometry>
        <mesh filename="package://rocr/meshes/link_front_right_tyre.STL"/>
      </geometry>
    </collision>
  </link>
  <joint name="joint_front_right_tyre" type="fixed">
    <origin rpy="0 0 0.63839" xyz="0 0 -0.012"/>
    <parent link="link_front_right_rim"/>
    <child link="link_front_right_tyre"/>
    <axis xyz="0 0 0"/>
  </joint>
  <transmission name="trans1">
    <type>transmission_interface/SimpleTransmission</type>
    <joint name="joint_rear_axle">
      <hardwareInterface>hardware_interface/VelocityJointInterface</hardwareInterface>
    </joint>
    <actuator name="RearEngine">
      <mechanicalReduction>1</mechanicalReduction>
    </actuator>
  </transmission>
  <transmission name="trans2">
    <type>transmission_interface/SimpleTransmission</type>
    <joint name="joint_front_left_axle">
      <hardwareInterface>hardware_interface/EffortJointInterface</hardwareInterface>
    </joint>
    <actuator name="F_L_motor_steer">
      <mechanicalReduction>1</mechanicalReduction>
    </actuator>
  </transmission>
  <transmission name="trans3">
    <type>transmission_interface/SimpleTransmission</type>
    <joint name="joint_front_right_axle">
      <hardwareInterface>hardware_interface/EffortJointInterface</hardwareInterface>
    </joint>
    <actuator name="F_R_motor_steer">
      <mechanicalReduction>1</mechanicalReduction>
    </actuator>
  </transmission>
  <transmission name="trans4">
    <type>transmission_interface/SimpleTransmission</type>
    <joint name="joint_left_arm">
      <hardwareInterface>hardware_interface/EffortJointInterface</hardwareInterface>
    </joint>
    <actuator name="Arm1">
      <hardwareInterface>hardware_interface/EffortJointInterface</hardwareInterface>
      <mechanicalReduction>1</mechanicalReduction>
    </actuator>
  </transmission>
  <transmission name="trans5">
    <type>transmission_interface/SimpleTransmission</type>
    <joint name="joint_right_arm">
      <hardwareInterface>hardware_interface/EffortJointInterface</hardwareInterface>
    </joint>
    <actuator name="Arm2">
      <hardwareInterface>hardware_interface/EffortJointInterface</hardwareInterface>
      <mechanicalReduction>1</mechanicalReduction>
    </actuator>
  </transmission>
  <link name="base_laser">
    <inertial>
      <origin rpy="0 0 0" xyz="-0.00029774 0.0066667 0.00013047"/>
      <mass value="0.15717"/>
      <inertia ixx="6.7885E-05" ixy="-1.3987E-07" ixz="-8.1554E-07" iyy="0.00013173" iyz="-9.0932E-08" izz="7.1972E-05"/>
    </inertial>
    <visual>
      <origin rpy="0 0 0" xyz="0 0 0"/>
      <geometry>
        <mesh filename="package://rocr/meshes/ydlidar.dae"/>
      </geometry>
      <material name="">
        <color rgba="0.64706 0.61961 0.58824 1"/>
      </material>
    </visual>
    <collision>
      <origin rpy="0 0 0" xyz="0 0 0"/>
      <geometry>
        <mesh filename="package://rocr/meshes/ydlidar.dae"/>
      </geometry>
    </collision>
  </link>
  <link name="laser_frame">
    <inertial>
      <origin rpy="0 0 0" xyz="-0.00036659 0.00064155 -0.00027052"/>
      <mass value="0.25482"/>
      <inertia ixx="8.9194E-05" ixy="1.8116E-07" ixz="3.6435E-08" iyy="0.00018279" iyz="2.423E-07" izz="0.00011103"/>
    </inertial>
  </link>
  <joint name="laser_joint" type="fixed">
    <origin rpy="0 0 90" xyz="0 0 1"/>
    <parent link="base_laser"/>
    <child link="laser_frame"/>
    <axis xyz="0 0 0"/>
  </joint>
  <!-- Add your gazebo sensors here -->
  <gazebo reference="base_laser">
    <!-- <gravity>true</gravity> -->
    <!-- Gazebo has fixed set of Sensors types. Check them out here <> -->
    <sensor name="laser" type="ray">
      <!-- Add in your sensor characteristics -->
      <pose> 0 0 0 0 0 0 </pose>
      <visualise>true</visualise>
      <update_rate>40</update_rate>
      <!-- <always_on>true</always_on> -->
      <ray>
        <scan>
          <horizontal>
            <samples>720</samples>
            <resolution>1</resolution>
            <min_angle>-1.570796</min_angle>
            <max_angle>1.570796</max_angle>
          </horizontal>
        </scan>
        <range>
          <min>0.10</min>
          <max>30.0</max>
          <resolution>0.01</resolution>
        </range>
        <noise>
          <type>gaussian</type>
          <mean>0.0</mean>
          <stddev>0.01</stddev>
        </noise>
      </ray>
      <plugin filename="libgazebo_ros_laser.so" name="gazebo_ros_head_hokuyo_controller">
        <!-- Use topic name as /my_robot/scan -->
        <topicName>/rocr/scan</topicName>
        <frameName>laser_frame</frameName>
      </plugin>
    </sensor>
  </gazebo>
  <!-- Add gazebo plugin for control here -->
  <gazebo>
    <plugin filename="libgazebo_ros_control.so" name="gazebo_ros_control">
      <robotNamespace>/rocr</robotNamespace>
      <robotSimType>gazebo_ros_control/DefaultRobotHWSim</robotSimType>
      <legacyModeNS>true</legacyModeNS>
    </plugin>
  </gazebo>
  <!-- Create a joint between your robot and sensor -->
  <joint name="laser_chassis" type="fixed">
    <origin rpy="0 0 3.14" xyz="-0.25 -0.05 0.028"/>
    <parent link="base_link"/>
    <child link="base_laser"/>
  </joint>
</robot>
